Workbook

Sheet Sheet1
A1: x | B1: x
A2: 11290001 | B2: =VLOOKUP(A2,'Master MAKT'!B:C,2,0) -> Empedu
A3: 11160004 | B3: =VLOOKUP(A3,'Master MAKT'!B:C,2,0) -> Serpihan BP
A4: 11170002 | B4: =VLOOKUP(A4,'Master MAKT'!B:C,2,0) -> Tembolok 10 Kg
A5: 11100001 | B5: =VLOOKUP(A5,'Master MAKT'!B:C,2,0) -> Head 10 Kg
A6: 11120001 | B6: =VLOOKUP(A6,'Master MAKT'!B:C,2,0) -> Usus 10 Kg Fresh
A7: 11130001 | B7: =VLOOKUP(A7,'Master MAKT'!B:C,2,0) -> Hati + Ampla (Giblet) Fresh
A8: 11110020 | B8: =VLOOKUP(A8,'Master MAKT'!B:C,2,0) -> Ceker tanpa Kuku 1 Kg Fr Hachi Grill
A9: 11140014 | B9: =VLOOKUP(A9,'Master MAKT'!B:C,2,0) -> Ampela 1 Kg Fr Hachi Grill
A10: 11150028 | B10: =VLOOKUP(A10,'Master MAKT'!B:C,2,0) -> Hati 1 Kg Fr Hachi Grill
A11: 11190001 | B11: =VLOOKUP(A11,'Master MAKT'!B:C,2,0) -> Skin neck RM Fresh
A12: 11300007 | B12: =VLOOKUP(A12,'Master MAKT'!B:C,2,0) -> Griller Size 2 (800-900 G) (10 E) Fresh
A13: 11320006 | B13: =VLOOKUP(A13,'Master MAKT'!B:C,2,0) -> Griller Size A (900-1000 G) General
... A37: 11730004 | B37: =VLOOKUP(A37,'Master MAKT'!B:C,2,0) -> Middle Wing 25-34 GR Fresh (RM)
A38: 1188003S | B38: =VLOOKUP(A38,'Master MAKT'!B:C,2,0) -> FW 90-100 G FZ POPOLAMAMA
A39: 11740052 | B39: =VLOOKUP(A39,'Master MAKT'!B:C,2,0) -> Wing Stick Frozen Pack
A40: 11730050 | B40: =VLOOKUP(A40,'Master MAKT'!B:C,2,0) -> Middle Wing Frozen Pack
A41: 11730003 | B41: =VLOOKUP(A41,'Master MAKT'!B:C,2,0) -> Middle Wing 18-48/23-48 Gr Fresh (RM)
A42: 11740002 | B42: =VLOOKUP(A42,'Master MAKT'!B:C,2,0) -> Wing Stick 18-48/23-48 Fresh (RM)
A43: 11110006 | B43: =VLOOKUP(A43,'Master MAKT'!B:C,2,0) -> Ceker By Product Fresh
A44: 11960001 | B44: =VLOOKUP(A44,'Master MAKT'!B:C,2,0) -> CCM 10 KG FRESH
A45: 111C0000 | B45: =VLOOKUP(A45,'Master MAKT'!B:C,2,0) -> MDM NY FRESH (BREAST)
A46: 11970002 | B46: =VLOOKUP(A46,'Master MAKT'!B:C,2,0) -> 1BP CCM
A47: 11320012 | B47: =VLOOKUP(A47,'Master MAKT'!B:C,2,0) -> Griller Size C (1100-1200 G) General
A48: 11260001 | B48: =VLOOKUP(A48,'Master MAKT'!B:C,2,0) -> Daging Potong BB (RM)
A49: 111B0000 | B49: =VLOOKUP(A49,'Master MAKT'!B:C,2,0) -> RM Reject (BP)
A50: 111C0004 | B50: =VLOOKUP(A50,'Master MAKT'!B:C,2,0) -> Daging Giling Ayam Utuh FR
A51: 11620056 | B51: =VLOOKUP(A51,'Master MAKT'!B:C,2,0) -> SBL Mitra 10 Kg
A52: 11240050 | B52: =VLOOKUP(A52,'Master MAKT'!B:C,2,0) -> Skin Carcass 4 KG Frozen
A53: 11310013 | B53: =VLOOKUP(A53,'Master MAKT'!B:C,2,0) -> Griller Size 1 ( 30 Ekor ) Frozen
A54: 11150068 | B54: =VLOOKUP(A54,'Master MAKT'!B:C,2,0) -> Hati 5 Kg Fz
A55: 11150066 | B55: =VLOOKUP(A55,'Master MAKT'!B:C,2,0) -> Hati Fz H-Nest
A56: 11150067 | B56: =VLOOKUP(A56,'Master MAKT'!B:C,2,0) -> Jantung Fz H-Nest
A57: 11140063 | B57: =VLOOKUP(A57,'Master MAKT'!B:C,2,0) -> Ampela Fz H-Nest
A58: 11190050 | B58: =VLOOKUP(A58,'Master MAKT'!B:C,2,0) -> Tulang Leher 5 Kg Frozen
A59: 11110074 | B59: =VLOOKUP(A59,'Master MAKT'!B:C,2,0) -> Ceker 1 KG Frozen
A60: 11140062 | B60: =VLOOKUP(A60,'Master MAKT'!B:C,2,0) -> Ampela 1 KG Frozen
A61: 11150064 | B61: =VLOOKUP(A61,'Master MAKT'!B:C,2,0) -> Hati 1 KG Frozen
A62: 11150065 | B62: =VLOOKUP(A62,'Master MAKT'!B:C,2,0) -> Jantung 1 KG Frozen
... A65: 11410008 | B65: =VLOOKUP(A65,'Master MAKT'!B:C,2,0) -> Parting 10 RM Fresh I Am Bensu
...

Sheet Master MAKT
A1: id | B1: MATNR | C1: MAKTX
A2: 326 | B2: 11660009 | C2: Drumstick 85-95 Gr Fresh
A3: 327 | B3: 11690059 | C3: SBB 5 Kg Frozen (25Kg)
A4: 328 | B4: 9903005 | C4: Bulu
A5: 329 | B5: 9903006 | C5: Darah
A6: 330 | B6: 9903008 | C6: Yellow Skin
A7: 331 | B7: 9903009 | C7: Isi Ampela Fresh
A8: 332 | B8: 11100001 | C8: Head 10 Kg
A9: 333 | B9: 11110006 | C9: Ceker By Product Fresh
A10: 334 | B10: 11110018 | C10: Ceker Fresh (Rumah Buah)
A11: 335 | B11: 11110020 | C11: Ceker tanpa Kuku 1 Kg Fr Hachi Grill
A12: 336 | B12: 11110051 | C12: Ceker By Product 5 Kg Frozen
A13: 337 | B13: 11110074 | C13: Ceker 1 KG Frozen
... A114: 438 | B114: 19990007 | C114: RM Beef Blade 20-30 G FR (5 Kg)
A115: 439 | B115: 111B0000 | C115: RM Reject (BP)
A116: 440 | B116: 111C0000 | C116: MDM NY FRESH (BREAST)
A117: 441 | B117: 111C0001 | C117: MDM NY Beku 5 Kg (BREAST)
A118: 442 | B118: 111C0004 | C118: Daging Giling Ayam Utuh FR
A119: 443 | B119: 1131000E | C119: Chicken Whole 800-900 G Fz Ismaya
A120: 444 | B120: 1132000M | C120: RM ATU
A121: 445 | B121: 1132000N | C121: Griller RM - < 700 G
A122: 446 | B122: 1132000O | C122: Griller RM - 1 (700-799 G)
A123: 447 | B123: 1132000P | C123: Griller RM - 2 (800-899 G)
A124: 448 | B124: 1132000Q | C124: Griller RM - A (900-999 G)
A125: 449 | B125: 1132000R | C125: Griller RM - B (1000-1099 G)
A126: 450 | B126: 1132000S | C126: Griller RM - C (1100-1199 G)
... A163: 487 | B163: 11950117R0 | C163: BL 100-110 THAI (BAKMI GM) Reject
A164: 659 | B164: 11110077 | C164: Ceker Ayam Fz Ismaya New
A165: 664 | B165: 11150027 | C165: Hati Ayam Fresh (Rumah Buah)
A166: 665 | B166: 11150028 | C166: Hati 1 Kg Fr Hachi Grill
A167: 689 | B167: 11320027 | C167: Griller Size G (1500-1600) Fresh
A168: 694 | B168: 11410043 | C168: Parting 10 Size D Fresh
A169: 697 | B169: 11420009 | C169: PARTING 12 SIZE C WO WING RM Fresh
A170: 699 | B170: 11450000 | C170: RM P-18 Size B FR
A171: 702 | B171: 11610009 | C171: BL BLOCK 15-25
A172: 711 | B172: 11640013 | C172: Paha Utuh Fresh (Rumah Buah)
A173: 713 | B173: 11640053 | C173: Bone In Leg Frozen Pack
A174: 714 | B174: 11640061 | C174: BIL FZ ABBQ
A175: 715 | B175: 11650009 | C175: THIGHSTICK FRESH R/M
... A182: 746 | B182: 11880044 | C182: RM Skin Neck Block Fresh
...
